<?xml version="1.0" ?>
<robot name="turtlebot3_burger" xmlns:xacro="http://ros.org/wiki/xacro">
  <xacro:include filename="$(find turtlebot3_description)/urdf/common_properties.xacro"/>
  <xacro:include filename="$(find turtlebot3_description)/urdf/turtlebot3_burger.gazebo.xacro"/>

  <!-- added by chengyuen21/11 -->

  <xacro:macro name="sonars" params="prefix parent_link yaw x y z">
    <xacro:macro name="sonar" params="prefix2">
      <link name="${prefix2}_sonar">
        <visual>
          <geometry>
            <cylinder radius="0.0125" length="0.01"/>
          </geometry>
          <material name="grey">
            <color rgba="0.3 0.3 0.3 1"/>
          </material>
          <origin rpy="0 1.5708 0"/>
        </visual>
      </link>
    </xacro:macro>

    <xacro:macro name="sonar_joint" params="prefix3 parent_link child_link yaw x y z">
      <joint name="${prefix3}_joint" type="fixed">
        <parent link="${parent_link}"/>
        <child link="${child_link}"/>
        <origin xyz="${x} ${y} ${z}" rpy="0 0 ${yaw}"/>
      </joint>
    </xacro:macro>

    <xacro:sonar prefix2="${prefix}_left"/>
    <xacro:sonar prefix2="${prefix}_right"/>
    <xacro:sonar_joint prefix3="${prefix}_left_sonar" parent_link="${parent_link}" child_link="${prefix}_left_sonar" yaw="${yaw}" x="${x}" y="${y}" z="${z}"/>
    <xacro:sonar_joint prefix3="${prefix}_right_sonar" parent_link="${parent_link}" child_link="${prefix}_right_sonar" yaw="${-yaw}" x="${x}" y="${-y}" z="${z}"/>


  </xacro:macro>

  <!-- added by chengyuen21/11 -->

  <link name="base_footprint"/>

  <joint name="base_joint" type="fixed">
    <parent link="base_footprint"/>
    <child link="base_link"/>
    <origin xyz="0.0 0.0 0.010" rpy="0 0 0"/>
  </joint>

  <link name="base_link">
    <visual>
      <origin xyz="-0.032 0 0.0" rpy="0 0 0"/>
      <geometry>
        <mesh filename="package://turtlebot3_description/meshes/bases/burger_base.stl" scale="0.001 0.001 0.001"/>
      </geometry>
      <material name="light_black"/>
    </visual>

    <collision>
      <origin xyz="-0.032 0 0.070" rpy="0 0 0"/>
      <geometry>
        <box size="0.140 0.140 0.140"/>
      </geometry>
    </collision>

    <inertial>
      <origin xyz="-0.032 0 0" rpy="0 0 0"/>
      <mass value="1"/>
      <inertia ixx="0.01" ixy="0.0" ixz="0.0"
               iyy="0.01" iyz="0.0"
               izz="0.01" />
    </inertial>
  </link>

  <joint name="wheel_left_joint" type="continuous">
    <parent link="base_link"/>
    <child link="wheel_left_link"/>
    <origin xyz="0.0 0.08 0.023" rpy="${-M_PI*0.5} 0 0"/>
    <axis xyz="0 0 1"/>
  </joint>

  <link name="wheel_left_link">
    <visual>
      <origin xyz="0 0 0" rpy="${M_PI*0.5} 0 0"/>
      <geometry>
        <mesh filename="package://turtlebot3_description/meshes/wheels/left_tire.stl" scale="0.001 0.001 0.001"/>
      </geometry>
      <material name="dark"/>
    </visual>

    <collision>
      <origin xyz="0 0 0" rpy="0 0 0"/>
      <geometry>
        <cylinder length="0.018" radius="0.033"/>
      </geometry>
    </collision>

    <inertial>
      <origin xyz="0 0 0" />
      <mass value="0.01" />
      <inertia ixx="0.001" ixy="0.0" ixz="0.0"
               iyy="0.001" iyz="0.0"
               izz="0.001" />
    </inertial>
  </link>

  <joint name="wheel_right_joint" type="continuous">
    <parent link="base_link"/>
    <child link="wheel_right_link"/>
    <origin xyz="0.0 -0.08 0.023" rpy="${-M_PI*0.5} 0 0"/>
    <axis xyz="0 0 1"/>
  </joint>

  <link name="wheel_right_link">
    <visual>
      <origin xyz="0 0 0" rpy="${M_PI*0.5} 0 0"/>
      <geometry>
        <mesh filename="package://turtlebot3_description/meshes/wheels/right_tire.stl" scale="0.001 0.001 0.001"/>
      </geometry>
      <material name="dark"/>
    </visual>

    <collision>
      <origin xyz="0 0 0" rpy="0 0 0"/>
      <geometry>
        <cylinder length="0.018" radius="0.033"/>
      </geometry>
    </collision>

    <inertial>
      <origin xyz="0 0 0" />
      <mass value="0.01" />
      <inertia ixx="0.001" ixy="0.0" ixz="0.0"
               iyy="0.001" iyz="0.0"
               izz="0.001" />
    </inertial>
  </link>

  <joint name="caster_back_joint" type="fixed">
    <parent link="base_link"/>
    <child link="caster_back_link"/>
    <origin xyz="-0.081 0 -0.004" rpy="${-M_PI*0.5} 0 0"/>
  </joint>

  <link name="caster_back_link">
    <collision>
      <origin xyz="0 0 0" rpy="0 0 0"/>
      <geometry>
        <box size="0.030 0.010 0.020"/>
      </geometry>
    </collision>

    <inertial>
      <origin xyz="0 0 0" />
      <mass value="0.01" />
      <inertia ixx="0.001" ixy="0.0" ixz="0.0"
               iyy="0.001" iyz="0.0"
               izz="0.001" />
    </inertial>
  </link>

  <joint name="imu_joint" type="fixed">
    <parent link="base_link"/>
    <child link="imu_link"/>
    <origin xyz="-0.032 0 0.068" rpy="0 0 0"/>
  </joint>

  <link name="imu_link"/>

  <joint name="scan_joint" type="fixed">
    <parent link="base_link"/>
    <child link="base_scan"/>
    <origin xyz="-0.032 0 0.171" rpy="0 0 0"/>
  </joint>

  <link name="base_scan">
    <visual>
      <origin xyz="0 0 0.0" rpy="0 0 0"/>
      <geometry>
        <mesh filename="package://turtlebot3_description/meshes/sensors/lds.stl" scale="0.001 0.001 0.001"/>
      </geometry>
      <material name="dark"/>
    </visual>

    <collision>
      <origin xyz="0 0 0" rpy="0 0 0"/>
      <geometry>
        <cylinder length="0.0408" radius="0.070"/>
      </geometry>
    </collision>

    <inertial>
      <mass value="0.01" />
      <origin xyz="0 0 0" />
      <inertia ixx="0.001" ixy="0.0" ixz="0.0"
               iyy="0.001" iyz="0.0"
               izz="0.001" />
    </inertial>
  </link>

  <!-- added by chengyuen21/11 -->

  <xacro:sonars prefix="upper_front1" parent_link="base_footprint" yaw="${40/180*3.14159}" x="0.03" y="0.06" z="0.15"/>
  <xacro:sonars prefix="main" parent_link="base_footprint" yaw="${10/180*3.14159}" x="0.05" y="0.02" z="0.15"/>

  <link name="gps">
    <visual>
      <geometry>
        <box size="0.02 0.02 0.01"/>
      </geometry>
    </visual>
  </link>

  <joint name="gps2basefootprint" type="fixed">
    <parent link="base_footprint"/>
    <child link="gps"/>
    <origin xyz="0 0 0.2"/>
  </joint>

  <!-- added by chengyuen21/11 -->

</robot>
